Workbook

Sheet Cover

Sheet Historical
A1: PayPal Holdings, Inc.
A2: Historical Financial Analysis
A5: $ in millions except per-share data | B5: 2021 | C5: 2022 | D5: 2023 | E5: 2024 | F5: 2025
A7: INCOME STATEMENT
A9: Revenue | B9: 25371 | C9: 27518 | D9: 29771 | E9: 31797 | F9: 33172
A10: Revenue Growth % | C10: =C9/B9-1 -> 0.084624177 | D10: =D9/C9-1 -> 0.081873683 | E10: 0.068 | F10: 0.043
A12: Transaction Expense | B12: 10315 | C12: 12173 | D12: 14385 | E12: 15697 | F12: 15987
A13: Transaction & Credit Losses | B13: 1060 | C13: 1572 | D13: 1682 | E13: 1442 | F13: 1720
A14: Customer Support & Operations | B14: 2075 | C14: 2120 | D14: 1919 | E14: 1768 | F14: 1704
A15: Sales & Marketing | B15: 2445 | C15: 2257 | D15: 1809 | E15: 2001 | F15: 2283
A16: Technology & Development | B16: 3038 | C16: 3253 | D16: 2973 | E16: 2979 | F16: 3103
A17: General & Administrative | B17: 2114 | C17: 2099 | D17: 2059 | E17: 2147 | F17: 1979
A18: Restructuring & Other | B18: 62 | C18: 207 | D18: -84 | E18: 438 | F18: 331
A19: Total Operating Expenses | B19: 21109 | C19: 23681 | D19: 24743 | E19: 26472 | F19: 27107
A21: Operating Income | B21: 4262 | C21: 3837 | D21: 5028 | E21: 5325 | F21: 6065
A22: Operating Margin % | B22: =B21/B9 -> 0.16798707 | C22: =C21/C9 -> 0.13943601 | D22: =D21/D9 -> 0.16888919 | E22: =E21/E9 -> 0.16746863 | F22: =F21/F9 -> 0.18283492
A24: Other Income / Expense | B24: -163 | C24: -471 | D24: 383 | E24: 4 | F24: 227
A25: Pre-Tax Income | B25: 4099 | C25: 3366 | D25: 5411 | E25: 5329 | F25: 6292
A26: Income Tax Expense | B26: -70 | C26: 947 | D26: 1165 | E26: 1182 | F26: 1059
A27: Effective Tax Rate % | B27: =B26/B25 -> -0.017077336 | C27: =C26/C25 -> 0.28134284 | D27: =D26/D25 -> 0.21530216 | E27: =E26/E25 -> 0.22180522 | F27: =F26/F25 -> 0.16830896
A29: Net Income | B29: 4169 | C29: 2419 | D29: 4246 | E29: 4147 | F29: 5233
A30: Net Margin % | B30: =B29/B9 -> 0.16432147 | C30: =C29/C9 -> 0.087906098 | D30: 0.143 | E30: 0.13 | F30: 0.158
A32: Diluted EPS | B32: 3.52 | C32: 2.09 | D32: 3.84 | E32: 3.99 | F32: 5.41
A33: Diluted Shares Outstanding | B33: 1186 | C33: 1158 | D33: 1107 | E33: 1039 | F33: 968
A37: BALANCE SHEET
A39: Cash & Cash Equivalents | B39: 5197 | C39: 7776 | D39: 9081 | E39: 6662 | F39: 8049
A40: Short-Term Investments | B40: 4303 | C40: 3092 | D40: 4979 | E40: 4262 | F40: 2373
A41: Accounts Receivable | B41: 800 | C41: 963 | D41: 1069 | E41: 984 | F41: 840
A42: Loans Receivable | B42: 4846 | C42: 7431 | D42: 5996 | E42: 6963 | F42: 8472
A43: Funds Receivable & Customer Accounts | B43: 36141 | C43: 36264 | D43: 38935 | E43: 37671 | F43: 38198
A44: Total Current Assets | B44: 52574 | C44: 57424 | D44: 62569 | E44: 58206 | F44: 59759
A46: Long-Term Investments | B46: 6797 | C46: 5018 | D46: 3273 | E46: 4583 | F46: 4330
A47: Property & Equipment | B47: 1909 | C47: 1730 | D47: 1488 | E47: 1508 | F47: 1700
A48: Goodwill | B48: 11454 | C48: 11209 | D48: 11026 | E48: 10837 | F48: 10864
A49: Intangible Assets | B49: 1332 | C49: 788 | D49: 537 | E49: 326 | F49: 208
A50: Other Assets | B50: 1737 | C50: 2455 | D50: 3273 | E50: 3265 | F50: 3312
A51: Total Assets | B51: 75803 | C51: 78624 | D51: 82166 | E51: 78725 | F51: 80173
... A62: Total Equity | B62: 21727 | C62: 20274 | D62: 21051 | E62: 20417 | F62: 20256
A66: CASH FLOW
A68: Operating Cash Flow | B68: 5797 | C68: 5813 | D68: 4843 | E68: 7450 | F68: 6416
...

Sheet Forecast
B5: 2025A | C5: 2026E | D5: 2027E | E5: 2028E | F5: 2029E | G5: 2030E
A7: REVENUE FORECAST
A9: Revenue | B9: =Historical!F9 -> 33172 | C9: =B9*(1+C10) -> 34830.6 | D9: =C9*(1+D10) -> 36746.283 | E9: =D9*(1+E10) -> 38767.329 | F9: =E9*(1+F10) -> 40705.695 | G9: =F9*(1+G10) -> 42537.451
A10: Revenue Growth % | C10: 0.05 | D10: 0.055 | E10: 0.055 | F10: 0.05 | G10: 0.045
A12: Operating Margin % | B12: =Historical!F22 -> 0.18283492 | C12: 0.185 | D12: 0.188 | E12: 0.19 | F12: 0.192 | G12: 0.193
A13: Operating Income | C13: =C9*C12 -> 6443.661 | D13: =D9*D12 -> 6908.3012 | E13: =E9*E12 -> 7365.7924 | F13: =F9*F12 -> 7815.4934 | G13: =G9*G12 -> 8209.7281
A15: Tax Rate % | C15: 0.19 | D15: 0.19 | E15: 0.19 | F15: 0.19 | G15: 0.19
A16: NOPAT | C16: =C13*(1-C15) -> 5219.3654 | D16: =D13*(1-D15) -> 5595.724 | E16: =E13*(1-E15) -> 5966.2919 | F16: =F13*(1-F15) -> 6330.5497 | G16: =G13*(1-G15) -> 6649.8798
A18: D&A | B18: =Historical!F75 -> 963 | C18: =C9*C19 -> 975.2568 | D18: =D9*D19 -> 1028.8959 | E18: =E9*E19 -> 1085.4852 | F18: =F9*F19 -> 1139.7595 | G18: =G9*G19 -> 1191.0486
A19: D&A / Revenue % | B19: =B18/B9 -> 0.029030508 | C19: 0.028 | D19: 0.028 | E19: 0.028 | F19: 0.028 | G19: 0.028
A21: CapEx | B21: =Historical!F69 -> 852 | C21: =C9*C22 -> 905.5956 | D21: =D9*D22 -> 955.40336 | E21: =E9*E22 -> 1007.9505 | F21: =F9*F22 -> 1058.3481 | G21: =G9*G22 -> 1105.9737
A22: CapEx / Revenue % | B22: 0.026 | C22: 0.026 | D22: 0.026 | E22: 0.026 | F22: 0.026 | G22: 0.026
A24: Change in NWC | C24: =C9*C25 -> 348.306 | D24: =D9*D25 -> 367.46283 | E24: =E9*E25 -> 387.67329 | F24: =F9*F25 -> 407.05695 | G24: =G9*G25 -> 425.37451
A25: Change in NWC / Revenue % | C25: 0.01 | D25: 0.01 | E25: 0.01 | F25: 0.01 | G25: 0.01
A27: Unlevered Free Cash Flow | C27: =C16+C18-C21-C24 -> 4940.7206 | D27: =D16+D18-D21-D24 -> 5301.7537 | E27: =E16+E18-E21-E24 -> 5656.1532 | F27: =F16+F18-F21-F24 -> 6004.9041 | G27: =G16+G18-G21-G24 -> 6309.5801

Sheet Summary
A1: PAYPAL EQUITY VALUATION SUMMARY
A3: Historical performance, DCF valuation and comparable-company cross-check
A5: VALUATION SNAPSHOT
A7: Current Market Price | B7: 52.53 | D7: Upside / Downside | E7: 0.658
A8: DCF Value | B8: 87.08 | D8: Revenue CAGR (2021–2025) | E8: 0.069
A9: Forward P/E Value | B9: 92.74 | D9: EPS CAGR (2021–2025) | E9: 0.113
A10: P / FCF Value | B10: 65.67 | D10: 2025 Operating Margin | E10: 0.183
A11: EV / EBITDA Value | B11: 49.17 | D11: 2025 FCF Margin | E11: 0.168
A13: KEY FINDINGS
A15: • Revenue grew at roughly 6.9% CAGR from 2021 to 2025, but annual growth slowed to 4.3% in 2025.
A16: • Operating margin improved to 18.3% in 2025, above the 2021 level.
A17: • EPS growth outpaced revenue growth, supported by a material reduction in diluted share count.
A18: • Free cash flow remained strong but was more volatile than revenue and earnings.
A19: • Valuation results vary meaningfully by methodology, highlighting sensitivity to assumptions and peer selection.
A21: VALUATION RANGE
A23: Method | B23: Implied Share Price | C23: Upside / Downside
A24: DCF | B24: 87.08 | C24: 0.658
A25: Forward P/E | B25: 92.74 | C25: 0.765
A26: P / FCF | B26: 65.67 | C26: 0.25
A27: EV / EBITDA | B27: 49.17 | C27: -0.064
A28: Current Market Price | B28: 52.53 | C28: -
A31: Interpretation: The DCF and forward P/E methods imply higher values than the current market price, while the EV/EBITDA cross-check is closer to the market. The range reflects differences in assumptions, capital structure, peer selection and the treatment of future cash-flow growth.

Sheet DCF
A2: WACC CALCULATION
A4: Risk-Free Rate | B4: 0.0529
A5: Beta | B5: 1.29
A6: Equity Risk Premium | B6: 0.0414
A7: Cost of Equity | B7: =B4+B5*B6 -> 0.106306
A9: Pre-Tax Cost of Debt | B9: 0.0511
A10: Tax Rate | B10: 0.19
A11: After-Tax Cost of Debt | B11: =B9*(1-B10) -> 0.041391
A13: Market Value of Equity | B13: 47085
A14: Debt | B14: 13400
A15: Total Capital | B15: =B13+B14 -> 60485
A17: Equity Weight | B17: =B13/B15 -> 0.77845747
A18: Debt Weight | B18: =B14/B15 -> 0.22154253
A20: WACC | B20: =B17*B7+B18*B11 -> 0.091924567
B24: 2026E | C24: 2027E | D24: 2028E | E24: 2029E | F24: 2030E
A25: Unlevered Free Cash Flow | B25: =Forecast!C27 -> 4940.7206 | C25: =Forecast!D27 -> 5301.7537 | D25: =Forecast!E27 -> 5656.1532 | E25: =Forecast!F27 -> 6004.9041 | F25: =Forecast!G27 -> 6309.5801
A26: Discount Period | B26: 1 | C26: 2 | D26: 3 | E26: 4 | F26: 5
A27: Discount Factor | B27: =1/(1+Sensitivity!$I$2)^B26 -> 0.91581418 | C27: =1/(1+Sensitivity!$I$2)^C26 -> 0.83871561 | D27: =1/(1+Sensitivity!$I$2)^D26 -> 0.76810765 | E27: =1/(1+Sensitivity!$I$2)^E26 -> 0.70344387 | F27: =1/(1+Sensitivity!$I$2)^F26 -> 0.64422387
A28: PV of UFCF | B28: =B25*B27 -> 4524.782 | C28: =C25*C27 -> 4446.6636 | D28: =D25*D27 -> 4344.5346 | E28: =E25*E27 -> 4224.113 | F28: =F25*F27 -> 4064.7822
A30: PV of Forecast UFCF | B30: =SUM(B28:F28) -> 21604.875 | C30: =SUM(C28:G28) -> 17080.093 | D30: =SUM(D28:H28) -> 12633.43 | E30: =SUM(E28:I28) -> 8288.8952 | F30: =SUM(F28:J28) -> 4064.7822
A32: Terminal Growth Rate | B32: 0.025
A33: Terminal Value | B33: =F25*(1+Sensitivity!$I$3)/(Sensitivity!$I$2-Sensitivity!$I$3) -> 96635.959
A34: PV of Terminal Value | B34: =B33*F27 -> 62255.192
A36: Enterprise Value | B36: =B30+B34 -> 83860.067
A38: Cash & Investments | B38: =8049+2373 -> 10422
A39: Debt | B39: 9987
A40: Equity Value | B40: =B36+B38-B39 -> 84295.067
A42: Diluted Shares Outstanding | B42: 968
A43: Implied Share Price | B43: =B40/B42 -> 87.081681

Sheet Comps
A2: COMPARABLE COMPANY ANALYSIS
A4: Company | B4: Market Cap ($M) | C4: Enterprise Value ($M) | D4: Forward P/E | E4: EV/Sales | F4: EV/EBITDA | G4: P/FCF
A5: PayPal | B5: use PYPL current | C5: use PYPL current | D5: use PYPL current | E5: use PYPL current | F5: use PYPL current | G5: use PYPL current
A6: Block | B6: 44316 | C6: 44749 | D6: 16.71 | E6: — | G6: 11.42
A7: Fiserv | B7: 24472 | C7: 51879 | D7: 6.25 | E7: 2.49 | F7: 6.71 | G7: 6.23
A8: Global Payments | B8: 21611 | C8: 39758 | D8: 5.56 | E8: 3.9 | F8: — | G8: 26.27
A9: Visa | B9: 659588 | C9: 669654 | D9: 25.3 | E9: ~15 | F9: — | G9: 31.55
A10: Mastercard | B10: 483093 | C10: 495984 | D10: 26.5 | E10: ~14 | F10: — | G10: 28.92
A12: Peer Median | B12: =MEDIAN(B6:B10) -> 44316 | C12: =MEDIAN(C6:C10) -> 51879 | D12: =MEDIAN(D6:D10) -> 16.71 | E12: =MEDIAN(E6:E10) -> 3.195 | F12: =MEDIAN(F6:F10) -> 6.71 | G12: =MEDIAN(G6:G10) -> 26.27
A13: Peer Average | B13: =AVERAGE(B6:B10) -> 246616 | C13: =AVERAGE(C6:C10) -> 260404.8 | D13: =AVERAGE(D6:D10) -> 16.064 | E13: =AVERAGE(E6:E10) -> 3.195 | F13: =AVERAGE(F6:F10) -> 6.71 | G13: =AVERAGE(G6:G10) -> 20.878
A16: PAYPAL IMPLIED VALUATION
A18: Method | B18: Peer Median Multiple | C18: PayPal Metric | D18: Implied Value | E18: Implied Share Price
A19: Forward P/E | B19: 16.71 | C19: 5.55 | D19: =B19*C19 -> 92.7405 | E19: =D19 -> 92.7405
A20: P / FCF | B20: =MEDIAN(G6:G8) -> 11.42 | C20: 5.75 | D20: =B20*C20 -> 65.665 | E20: =D20 -> 65.665
A21: EV / EBITDA | B21: =MEDIAN(F6:F8) -> 6.71 | C21: 7028 | D21: =B21*C21 -> 47157.88 | E21: =D21+10422-9987 -> 47592.88 | F21: =E21/968 -> 49.166198
A24: VALUATION SUMMARY
C25: Upside / Downside
A26: DCF | B26: 87.08 | C26: =B26/$B$31-1 -> 0.6577194
A27: Forward P/E | B27: 92.74 | C27: =B27/$B$31-1 -> 0.76546735
A28: P / FCF | B28: 65.67 | C28: =B28/$B$31-1 -> 0.25014278
A29: EV / EBITDA | B29: 49.17 | C29: =B29/$B$31-1 -> -0.063963449
A31: Current Market Price | B31: 52.53 | C31: =B31/$B$31-1 -> 0

Sheet Sensitivity
A2: DCF SENSITIVITY ANALYSIS | H2: WACC Input | I2: =DCF!B20 -> 0.091924567
H3: Terminal Growth Input | I3: =DCF!B32 -> 0.025
A4: Implied Share Price | D4: WACC
A5: =DCF!B43 -> 87.081681 | B5: 0.08 | C5: 0.085 | D5: 0.09 | E5: 0.095 | F5: 0.1
A6: 0.02 | B6: 98.919894 | C6: 91.215956 | D6: 84.614657 | E6: 78.895426 | F6: 73.892833
A7: 0.025 | B7: 106.17905 | C7: 97.245876 | D7: 89.688976 | E7: 83.213393 | F7: 77.602826
A8: 0.03 | B8: 114.89004 | C8: 104.37214 | D8: 95.609014 | E8: 88.195663 | F8: 81.842819
A9: 0.035 | B9: 125.5368 | C9: 112.92367 | D9: 102.60542 | E9: 94.008311 | F9: 86.735117
A10: Terminal Growth
A12: INTERPRETATION
A13: The DCF valuation is most sensitive to the discount rate
A14: and terminal growth assumption. Lower discount rates and
A15: higher terminal growth rates produce materially higher
A16: implied equity values.
A17: The DCF suggests a range of potential intrinsic values depending on long-term growth and required return assumptions.
